Workbook

Sheet  Sales analysis
A1: Order_ID | B1: Order_Date | C1: Customer | D1: Product | E1: Category | F1: Region | G1: Quantity | H1: Sales | I1: Discount | J1: Profit | K1: clean category
A2: 10001 | B2: 45802 | C2: Ananya | D2: Desk | E2: Furniture | F2: South | G2: 3 | H2: 11474.08 | I2: 0.25 | J2: 1208.74 | K2: Furniture
A3: 10002 | B3: 45858 | C3: Priya | D3: Monitor | E3: Technology | F3: North | G3: 7 | H3: 1084.2 | I3: 0.2 | J3: 2189.43 | K3: Technology
A4: 10003 | B4: 45869 | C4: Sneha | D4: Headphones | E4: Technology | F4: North | G4: 3 | H4: 47503.67 | I4: 0.25 | J4: 9580.29 | K4: Technology
A5: 10004 | B5: 45877 | C5: Rahul | D5: Desk | E5: Furniture | F5: North | G5: 3 | H5: 33851.67 | I5: 0.2 | J5: 8146.67 | K5: Furniture
A6: 10005 | B6: 45897 | C6: Priya | D6: Keyboard | E6: Technology | F6: South | G6: 2 | H6: 10503.48 | I6: 0 | J6: 6585.8 | K6: Technology
A7: 10006 | B7: 45703 | C7: Priya | D7: Chair | E7: Furniture | F7: West | G7: 6 | H7: 71866.09 | I7: 0.15 | J7: 5727.32 | K7: Furniture
A8: 10007 | B8: 45692 | C8: Ananya | D8: Headphones | E8: Technology | F8: North | G8: 6 | H8: 39959.65 | I8: 0.25 | J8: 11073.09 | K8: Technology
A9: 10008 | B9: 45910 | C9: Sneha | D9: Headphones | E9: Technology | F9: South | G9: 6 | H9: 18521.05 | I9: 0.2 | J9: 919.18 | K9: Technology
A10: 10009 | B10: 45739 | C10: Rohan | D10: Desk | E10: Furniture | F10: West | G10: 4 | H10: 37794.97 | I10: 0.05 | J10: 3403.18 | K10: Furniture
A11: 10010 | B11: 45913 | C11: Vikram | D11: Mouse | E11: Technology | F11: North | G11: 5 | H11: 51131.71 | I11: 0.05 | J11: 4231.76 | K11: Technology
A12: 10011 | B12: 45854 | C12: Neha | D12: Keyboard | E12: Technology | F12: East | G12: 6 | H12: 6179.82 | I12: 0.25 | J12: 9399.99 | K12: Technology
A13: 10012 | B13: 45960 | C13: Neha | D13: Desk | E13: Furniture | F13: West | G13: 3 | H13: 20965.43 | I13: 0.15 | J13: 11910.55 | K13: Furniture
... A146: 10145 | B146: 45679 | C146: Vikram | D146: Chair | E146: Furniture | F146: South | G146: 2 | H146: 39427.01 | I146: 0.15 | J146: 8114.97 | K146: Furniture
A147: 10146 | B147: 45983 | C147: Priya | D147: Desk | E147: Furniture | F147: West | G147: 3 | I147: 0.1 | J147: 2906.84 | K147: Furniture
A148: 10147 | B148: 45658 | C148: Ananya | D148: Keyboard | E148: Technology | F148: West | G148: 7 | H148: 72994.32 | I148: 0.05 | J148: 9108.58 | K148: Technology
A149: 10148 | B149: 45790 | C149: Sneha | D149: Keyboard | E149: Technology | F149: West | G149: 1 | H149: 17346.34 | I149: 0.15 | J149: 9132.07 | K149: Technology
A150: 10149 | B150: 45890 | C150: Priya | D150: Laptop | E150: Technology | F150: South | G150: 1 | H150: 23162.8 | I150: 0.2 | J150: 3785.55 | K150: Technology
A151: 10150 | B151: 45669 | C151: Ananya | D151: Chair | E151: Furniture | F151: West | G151: 7 | H151: 23143.72 | I151: 0.2 | J151: 4957.66 | K151: Furniture
A152: 10151 | B152: 46003 | C152: Rohan | D152: Keyboard | E152: Technology | F152: East | G152: 6 | H152: 17666.04 | I152: 0 | J152: 2555.8 | K152: Technology
A153: 10152 | B153: 45703 | C153: Rohan | D153: Keyboard | E153: Technology | F153: North | G153: 6 | H153: 609.8 | I153: 0.1 | J153: 11719.9 | K153: Technology
A154: 10153 | B154: 45691 | C154: Ananya | D154: Laptop | E154: Technology | F154: North | G154: 6 | H154: 54836.19 | I154: 0.05 | J154: 7764.95 | K154: Technology
A155: 10154 | B155: 45735 | C155: Sneha | D155: Keyboard | E155: Technology | F155: West | G155: 1 | H155: 72529.99 | I155: 0 | J155: 11217.8 | K155: Technology
A156: 10155 | B156: 45875 | C156: Rahul | D156: Headphones | E156: Technology | F156: North | G156: 2 | H156: 17209.86 | I156: 0.1 | J156: 3675.46 | K156: Technology
A157: 10156 | B157: 45958 | C157: Vikram | D157: Mouse | E157: Technology | F157: South | G157: 1 | H157: 49897.02 | I157: 0.15 | J157: 9393.6 | K157: Technology
A158: 10157 | B158: 45730 | C158: Aarav | D158: Desk | E158: Furniture | F158: South | G158: 5 | H158: 55771.28 | I158: 0.2 | J158: 9202.01 | K158: Furniture
A159: 10158 | B159: 45939 | C159: Aarav | D159: Mouse | E159: Technology | F159: North | G159: 4 | H159: 63707.69 | I159: 0.25 | J159: 8315.29 | K159: Technology
... A212: 10211 | B212: 45783 | C212: Sneha | D212: Desk | E212: Furniture | F212: East | G212: 3 | H212: 28848.57 | I212: 0 | J212: 7964.65 | K212: Furniture
A213: 10212 | B213: 45957 | C213: Rahul | D213: Desk | E213: Furniture | F213: West | G213: 6 | H213: 12646.13 | I213: 0.2 | K213: Furniture
A214: 10213 | B214: 45682 | C214: Vikram | D214: Headphones | E214: Technology | F214: East | G214: 3 | H214: 59072.32 | I214: 0.05 | J214: 9752.76 | K214: Technology
A215: 10214 | B215: 45802 | C215: Rahul | D215: Desk | E215: Furniture | F215: West | G215: 3 | H215: 55216.07 | I215: 0.15 | J215: 11351.71 | K215: Furniture
A216: 10215 | B216: 45670 | C216: Rahul | D216: Keyboard | E216: Technology | F216: North | G216: 5 | H216: 29134.45 | I216: 0.25 | J216: 3789.39 | K216: Technology
A217: 10216 | B217: 45869 | C217: Ananya | D217: Headphones | E217: Technology | F217: North | G217: 7 | H217: 2376.91 | I217: 0.1 | J217: 10309.15 | K217: Technology
A218: 10217 | B218: 45682 | C218: Aarav | D218: Monitor | E218: Technology | F218: West | G218: 6 | H218: 63005.3 | I218: 0.1 | J218: 1623.66 | K218: Technology
A219: 10218 | B219: 45725 | C219: Ananya | D219: Headphones | E219: Technology | F219: North | G219: 5 | H219: 1350.64 | I219: 0.05 | J219: 8475.24 | K219: Technology
A220: 10219 | B220: 45724 | C220: Aarav | D220: Chair | E220: Furniture | F220: West | G220: 1 | H220: 52925.63 | I220: 0.1 | J220: 8916.63 | K220: Furniture
A221: 10220 | B221: 45890 | C221: Rohan | D221: Desk | E221: Furniture | F221: South | G221: 4 | H221: 72784.15 | I221: 0.1 | J221: 8148.79 | K221: Furniture
A222: 10221 | B222: 45766 | C222: Rohan | D222: Keyboard | E222: Technology | F222: East | G222: 3 | H222: 33105.77 | I222: 0 | J222: 3065.16 | K222: Technology
A223: 10222 | B223: 45803 | C223: Sneha | D223: Keyboard | E223: Technology | F223: South | G223: 4 | H223: 18005.52 | I223: 0.15 | J223: 10482.87 | K223: Technology
A224: 10223 | B224: 45768 | C224: Aarav | D224: Printer | E224: Technology | F224: West | G224: 5 | H224: 53012.89 | I224: 0.15 | J224: 2067.86 | K224: Technology
...

Sheet  Pivot analysis
A1: Sales analysis
D2: Count of Order_ID | G2: Sum of Quantity | I2: Average Order Value
A3: Sum of Sales | D3: 1000 | G3: 3979 | I3: =A4/D3 -> 37613.933
A4: 37613933
A8: Row Labels | B8: Sum of Sales | D8: Row Labels | E8: Sum of Sales | G8: Row Labels | H8: Sum of Sales
A9: Furniture | B9: 9579344.6 | D9: East | E9: 8744277.3 | G9: Jan | H9: 3511075.3
A10: Technology | B10: 28034588 | D10: North | E10: 9169887.8 | G10: Feb | H10: 2986620.1
A11: Grand Total | B11: 37613933 | D11: South | E11: 9321539.8 | G11: Mar | H11: 3321371.3
D12: West | E12: 10378228 | G12: Apr | H12: 3311249.4
D13: Grand Total | E13: 37613933 | G13: May | H13: 3168773.9
G14: Jun | H14: 2952237
G15: Jul | H15: 2548735.3
G16: Aug | H16: 3665492.1
G17: Sep | H17: 2742406
G18: Oct | H18: 3161107.8
G19: Nov | H19: 3077908.8
G20: Dec | H20: 3166955.6
G21: Grand Total | H21: 37613933
A23: Profit analysis
A25: Row Labels | B25: Sum of Sales | D25: Row Labels | E25: Sum of Profit
A26: Aarav | B26: 4288975.7 | D26: Furniture | E26: 1457772.1
A27: Ananya | B27: 5489480.8 | D27: Technology | E27: 4556311.4
A28: Neha | B28: 5386624.2 | D28: Grand Total | E28: 6014083.4
A29: Priya | B29: 5382946.6
A30: Rahul | B30: 3886212
A31: Rohan | B31: 4478718.6
A32: Sneha | B32: 4179045.8
A33: Unknown | B33: 100500.7
A34: Vikram | B34: 4421428.4
A35: Grand Total | B35: 37613933
A45: Sum of Profit
A46: 6002282.5

Sheet Interactive Dashboard
A1: SALES ANALYTICS DASHBOARD
A4: CATEGORY | C4: All | F4: REGION | H4: All | K4: CUSTOMER | M4: All
A6: TOTAL SALES | E6: TOTAL ORDERS | I6: TOTAL QUANTITY | M6: AVERAGE ORDER VALUE
A7: =SUMIFS(' Sales analysis'!$H$2:$H$1001,' Sales analysis'!$E$2:$E$1001,IF($C$4="All","<>",$C$4),' Sales analysis'!$F$2:$F$1001,IF($H$4="All","<>",$H$4),' Sales analysis'!$C$2:$C$1001,IF($M$4="All","<>",$M$4)) -> 37613933 | E7: =COUNTIFS(' Sales analysis'!$E$2:$E$1001,IF($C$4="All","<>",$C$4),' Sales analysis'!$F$2:$F$1001,IF($H$4="All","<>",$H$4),' Sales analysis'!$C$2:$C$1001,IF($M$4="All","<>",$M$4)) -> 1000 | I7: =SUMIFS(' Sales analysis'!$G$2:$G$1001,' Sales analysis'!$E$2:$E$1001,IF($C$4="All","<>",$C$4),' Sales analysis'!$F$2:$F$1001,IF($H$4="All","<>",$H$4),' Sales analysis'!$C$2:$C$1001,IF($M$4="All","<>",$M$4)) -> 3979 | M7: =IFERROR(A7/E7,0) -> 37613.933
A40: Use the filters above to interactively analyze sales performance.

Sheet _Dashboard_Helper
A1: Category | B1: Region | C1: Customer | E1: Month | F1: Sales | I1: Category | J1: Sales | L1: Region | M1: Sales | O1: Customer | P1: Sales | R1: Top Customer | S1: Sales
A2: All | B2: All | C2: All | E2: Jan | F2: =SUMIFS(' Sales analysis'!$H$2:$H$1001,' Sales analysis'!$E$2:$E$1001,IF('Interactive Dashboard'!$C$4="All","<>",'Interactive Dashboard'!$C$4),' Sales analysis'!$F$2:$F$1001,IF('Interactive Dashboard'!$H$4="All","<>",'Interactive Dashboard'!$H$4),' Sales analysis'!$C$2:$C$1001,IF('Interactive Dashboard'!$M$4="All","<>",'Interactive Dashboard'!$M$4),' Sales analysis'!$B$2:$B$1001,">="&DATE(2025,1,1),' Sales analysis'!$B$2:$B$1001,"<"&EDATE(DATE(2025,1,1),1)) -> 3511075.3 | I2: Furniture | J2: =SUMIFS(' Sales analysis'!$H$2:$H$1001,' Sales analysis'!$E$2:$E$1001,I2,' Sales analysis'!$E$2:$E$1001,IF('Interactive Dashboard'!$C$4="All","<>",'Interactive Dashboard'!$C$4),' Sales analysis'!$F$2:$F$1001,IF('Interactive Dashboard'!$H$4="All","<>",'Interactive Dashboard'!$H$4),' Sales analysis'!$C$2:$C$1001,IF('Interactive Dashboard'!$M$4="All","<>",'Interactive Dashboard'!$M$4)) -> 9579344.6 | L2: East | M2: =SUMIFS(' Sales analysis'!$H$2:$H$1001,' Sales analysis'!$F$2:$F$1001,L2,' Sales analysis'!$E$2:$E$1001,IF('Interactive Dashboard'!$C$4="All","<>",'Interactive Dashboard'!$C$4),' Sales analysis'!$F$2:$F$1001,IF('Interactive Dashboard'!$H$4="All","<>",'Interactive Dashboard'!$H$4),' Sales analysis'!$C$2:$C$1001,IF('Interactive Dashboard'!$M$4="All","<>",'Interactive Dashboard'!$M$4)) -> 8744277.3 | O2: Ananya | P2: =SUMIFS(' Sales analysis'!$H$2:$H$1001,' Sales analysis'!$C$2:$C$1001,O2,' Sales analysis'!$E$2:$E$1001,IF('Interactive Dashboard'!$C$4="All","<>",'Interactive Dashboard'!$C$4),' Sales analysis'!$F$2:$F$1001,IF('Interactive Dashboard'!$H$4="All","<>",'Interactive Dashboard'!$H$4),' Sales analysis'!$C$2:$C$1001,IF('Interactive Dashboard'!$M$4="All","<>",'Interactive Dashboard'!$M$4)) -> 5489480.8 | R2: =IFERROR(INDEX($O$2:$O$10,MATCH(S2,$P$2:$P$10,0)),"") -> Ananya | S2: =IFERROR(LARGE($P$2:$P$10,1),0) -> 5489480.8
A3: Furniture | B3: East | C3: Ananya | E3: Feb | F3: =SUMIFS(' Sales analysis'!$H$2:$H$1001,' Sales analysis'!$E$2:$E$1001,IF('Interactive Dashboard'!$C$4="All","<>",'Interactive Dashboard'!$C$4),' Sales analysis'!$F$2:$F$1001,IF('Interactive Dashboard'!$H$4="All","<>",'Interactive Dashboard'!$H$4),' Sales analysis'!$C$2:$C$1001,IF('Interactive Dashboard'!$M$4="All","<>",'Interactive Dashboard'!$M$4),' Sales analysis'!$B$2:$B$1001,">="&DATE(2025,2,1),' Sales analysis'!$B$2:$B$1001,"<"&EDATE(DATE(2025,2,1),1)) -> 2986620.1 | I3: Technology | J3: =SUMIFS(' Sales analysis'!$H$2:$H$1001,' Sales analysis'!$E$2:$E$1001,I3,' Sales analysis'!$E$2:$E$1001,IF('Interactive Dashboard'!$C$4="All","<>",'Interactive Dashboard'!$C$4),' Sales analysis'!$F$2:$F$1001,IF('Interactive Dashboard'!$H$4="All","<>",'Interactive Dashboard'!$H$4),' Sales analysis'!$C$2:$C$1001,IF('Interactive Dashboard'!$M$4="All","<>",'Interactive Dashboard'!$M$4)) -> 28034588 | L3: North | M3: =SUMIFS(' Sales analysis'!$H$2:$H$1001,' Sales analysis'!$F$2:$F$1001,L3,' Sales analysis'!$E$2:$E$1001,IF('Interactive Dashboard'!$C$4="All","<>",'Interactive Dashboard'!$C$4),' Sales analysis'!$F$2:$F$1001,IF('Interactive Dashboard'!$H$4="All","<>",'Interactive Dashboard'!$H$4),' Sales analysis'!$C$2:$C$1001,IF('Interactive Dashboard'!$M$4="All","<>",'Interactive Dashboard'!$M$4)) -> 9169887.8 | O3: Priya | P3: =SUMIFS(' Sales analysis'!$H$2:$H$1001,' Sales analysis'!$C$2:$C$1001,O3,' Sales analysis'!$E$2:$E$1001,IF('Interactive Dashboard'!$C$4="All","<>",'Interactive Dashboard'!$C$4),' Sales analysis'!$F$2:$F$1001,IF('Interactive Dashboard'!$H$4="All","<>",'Interactive Dashboard'!$H$4),' Sales analysis'!$C$2:$C$1001,IF('Interactive Dashboard'!$M$4="All","<>",'Interactive Dashboard'!$M$4)) -> 5382946.6 | R3: =IFERROR(INDEX($O$2:$O$10,MATCH(S3,$P$2:$P$10,0)),"") -> Neha | S3: =IFERROR(LARGE($P$2:$P$10,2),0) -> 5386624.2
A4: Technology | B4: North | C4: Priya | E4: Mar | F4: =SUMIFS(' Sales analysis'!$H$2:$H$1001,' Sales analysis'!$E$2:$E$1001,IF('Interactive Dashboard'!$C$4="All","<>",'Interactive Dashboard'!$C$4),' Sales analysis'!$F$2:$F$1001,IF('Interactive Dashboard'!$H$4="All","<>",'Interactive Dashboard'!$H$4),' Sales analysis'!$C$2:$C$1001,IF('Interactive Dashboard'!$M$4="All","<>",'Interactive Dashboard'!$M$4),' Sales analysis'!$B$2:$B$1001,">="&DATE(2025,3,1),' Sales analysis'!$B$2:$B$1001,"<"&EDATE(DATE(2025,3,1),1)) -> 3321371.3 | L4: South | M4: =SUMIFS(' Sales analysis'!$H$2:$H$1001,' Sales analysis'!$F$2:$F$1001,L4,' Sales analysis'!$E$2:$E$1001,IF('Interactive Dashboard'!$C$4="All","<>",'Interactive Dashboard'!$C$4),' Sales analysis'!$F$2:$F$1001,IF('Interactive Dashboard'!$H$4="All","<>",'Interactive Dashboard'!$H$4),' Sales analysis'!$C$2:$C$1001,IF('Interactive Dashboard'!$M$4="All","<>",'Interactive Dashboard'!$M$4)) -> 9321539.8 | O4: Sneha | P4: =SUMIFS(' Sales analysis'!$H$2:$H$1001,' Sales analysis'!$C$2:$C$1001,O4,' Sales analysis'!$E$2:$E$1001,IF('Interactive Dashboard'!$C$4="All","<>",'Interactive Dashboard'!$C$4),' Sales analysis'!$F$2:$F$1001,IF('Interactive Dashboard'!$H$4="All","<>",'Interactive Dashboard'!$H$4),' Sales analysis'!$C$2:$C$1001,IF('Interactive Dashboard'!$M$4="All","<>",'Interactive Dashboard'!$M$4)) -> 4179045.8 | R4: =IFERROR(INDEX($O$2:$O$10,MATCH(S4,$P$2:$P$10,0)),"") -> Priya | S4: =IFERROR(LARGE($P$2:$P$10,3),0) -> 5382946.6
B5: South | C5: Sneha | E5: Apr | F5: =SUMIFS(' Sales analysis'!$H$2:$H$1001,' Sales analysis'!$E$2:$E$1001,IF('Interactive Dashboard'!$C$4="All","<>",'Interactive Dashboard'!$C$4),' Sales analysis'!$F$2:$F$1001,IF('Interactive Dashboard'!$H$4="All","<>",'Interactive Dashboard'!$H$4),' Sales analysis'!$C$2:$C$1001,IF('Interactive Dashboard'!$M$4="All","<>",'Interactive Dashboard'!$M$4),' Sales analysis'!$B$2:$B$1001,">="&DATE(2025,4,1),' Sales analysis'!$B$2:$B$1001,"<"&EDATE(DATE(2025,4,1),1)) -> 3311249.4 | L5: West | M5: =SUMIFS(' Sales analysis'!$H$2:$H$1001,' Sales analysis'!$F$2:$F$1001,L5,' Sales analysis'!$E$2:$E$1001,IF('Interactive Dashboard'!$C$4="All","<>",'Interactive Dashboard'!$C$4),' Sales analysis'!$F$2:$F$1001,IF('Interactive Dashboard'!$H$4="All","<>",'Interactive Dashboard'!$H$4),' Sales analysis'!$C$2:$C$1001,IF('Interactive Dashboard'!$M$4="All","<>",'Interactive Dashboard'!$M$4)) -> 10378228 | O5: Rahul | P5: =SUMIFS(' Sales analysis'!$H$2:$H$1001,' Sales analysis'!$C$2:$C$1001,O5,' Sales analysis'!$E$2:$E$1001,IF('Interactive Dashboard'!$C$4="All","<>",'Interactive Dashboard'!$C$4),' Sales analysis'!$F$2:$F$1001,IF('Interactive Dashboard'!$H$4="All","<>",'Interactive Dashboard'!$H$4),' Sales analysis'!$C$2:$C$1001,IF('Interactive Dashboard'!$M$4="All","<>",'Interactive Dashboard'!$M$4)) -> 3886212 | R5: =IFERROR(INDEX($O$2:$O$10,MATCH(S5,$P$2:$P$10,0)),"") -> Rohan | S5: =IFERROR(LARGE($P$2:$P$10,4),0) -> 4478718.6
B6: West | C6: Rahul | E6: May | F6: =SUMIFS(' Sales analysis'!$H$2:$H$1001,' Sales analysis'!$E$2:$E$1001,IF('Interactive Dashboard'!$C$4="All","<>",'Interactive Dashboard'!$C$4),' Sales analysis'!$F$2:$F$1001,IF('Interactive Dashboard'!$H$4="All","<>",'Interactive Dashboard'!$H$4),' Sales analysis'!$C$2:$C$1001,IF('Interactive Dashboard'!$M$4="All","<>",'Interactive Dashboard'!$M$4),' Sales analysis'!$B$2:$B$1001,">="&DATE(2025,5,1),' Sales analysis'!$B$2:$B$1001,"<"&EDATE(DATE(2025,5,1),1)) -> 3168773.9 | O6: Rohan | P6: =SUMIFS(' Sales analysis'!$H$2:$H$1001,' Sales analysis'!$C$2:$C$1001,O6,' Sales analysis'!$E$2:$E$1001,IF('Interactive Dashboard'!$C$4="All","<>",'Interactive Dashboard'!$C$4),' Sales analysis'!$F$2:$F$1001,IF('Interactive Dashboard'!$H$4="All","<>",'Interactive Dashboard'!$H$4),' Sales analysis'!$C$2:$C$1001,IF('Interactive Dashboard'!$M$4="All","<>",'Interactive Dashboard'!$M$4)) -> 4478718.6 | R6: =IFERROR(INDEX($O$2:$O$10,MATCH(S6,$P$2:$P$10,0)),"") -> Vikram | S6: =IFERROR(LARGE($P$2:$P$10,5),0) -> 4421428.4
C7: Rohan | E7: Jun | F7: =SUMIFS(' Sales analysis'!$H$2:$H$1001,' Sales analysis'!$E$2:$E$1001,IF('Interactive Dashboard'!$C$4="All","<>",'Interactive Dashboard'!$C$4),' Sales analysis'!$F$2:$F$1001,IF('Interactive Dashboard'!$H$4="All","<>",'Interactive Dashboard'!$H$4),' Sales analysis'!$C$2:$C$1001,IF('Interactive Dashboard'!$M$4="All","<>",'Interactive Dashboard'!$M$4),' Sales analysis'!$B$2:$B$1001,">="&DATE(2025,6,1),' Sales analysis'!$B$2:$B$1001,"<"&EDATE(DATE(2025,6,1),1)) -> 2952237 | O7: Vikram | P7: =SUMIFS(' Sales analysis'!$H$2:$H$1001,' Sales analysis'!$C$2:$C$1001,O7,' Sales analysis'!$E$2:$E$1001,IF('Interactive Dashboard'!$C$4="All","<>",'Interactive Dashboard'!$C$4),' Sales analysis'!$F$2:$F$1001,IF('Interactive Dashboard'!$H$4="All","<>",'Interactive Dashboard'!$H$4),' Sales analysis'!$C$2:$C$1001,IF('Interactive Dashboard'!$M$4="All","<>",'Interactive Dashboard'!$M$4)) -> 4421428.4 | R7: =IFERROR(INDEX($O$2:$O$10,MATCH(S7,$P$2:$P$10,0)),"") -> Aarav | S7: =IFERROR(LARGE($P$2:$P$10,6),0) -> 4288975.7
C8: Vikram | E8: Jul | F8: =SUMIFS(' Sales analysis'!$H$2:$H$1001,' Sales analysis'!$E$2:$E$1001,IF('Interactive Dashboard'!$C$4="All","<>",'Interactive Dashboard'!$C$4),' Sales analysis'!$F$2:$F$1001,IF('Interactive Dashboard'!$H$4="All","<>",'Interactive Dashboard'!$H$4),' Sales analysis'!$C$2:$C$1001,IF('Interactive Dashboard'!$M$4="All","<>",'Interactive Dashboard'!$M$4),' Sales analysis'!$B$2:$B$1001,">="&DATE(2025,7,1),' Sales analysis'!$B$2:$B$1001,"<"&EDATE(DATE(2025,7,1),1)) -> 2548735.3 | O8: Neha | P8: =SUMIFS(' Sales analysis'!$H$2:$H$1001,' Sales analysis'!$C$2:$C$1001,O8,' Sales analysis'!$E$2:$E$1001,IF('Interactive Dashboard'!$C$4="All","<>",'Interactive Dashboard'!$C$4),' Sales analysis'!$F$2:$F$1001,IF('Interactive Dashboard'!$H$4="All","<>",'Interactive Dashboard'!$H$4),' Sales analysis'!$C$2:$C$1001,IF('Interactive Dashboard'!$M$4="All","<>",'Interactive Dashboard'!$M$4)) -> 5386624.2 | R8: =IFERROR(INDEX($O$2:$O$10,MATCH(S8,$P$2:$P$10,0)),"") -> Sneha | S8: =IFERROR(LARGE($P$2:$P$10,7),0) -> 4179045.8
C9: Neha | E9: Aug | F9: =SUMIFS(' Sales analysis'!$H$2:$H$1001,' Sales analysis'!$E$2:$E$1001,IF('Interactive Dashboard'!$C$4="All","<>",'Interactive Dashboard'!$C$4),' Sales analysis'!$F$2:$F$1001,IF('Interactive Dashboard'!$H$4="All","<>",'Interactive Dashboard'!$H$4),' Sales analysis'!$C$2:$C$1001,IF('Interactive Dashboard'!$M$4="All","<>",'Interactive Dashboard'!$M$4),' Sales analysis'!$B$2:$B$1001,">="&DATE(2025,8,1),' Sales analysis'!$B$2:$B$1001,"<"&EDATE(DATE(2025,8,1),1)) -> 3665492.1 | O9: Unknown | P9: =SUMIFS(' Sales analysis'!$H$2:$H$1001,' Sales analysis'!$C$2:$C$1001,O9,' Sales analysis'!$E$2:$E$1001,IF('Interactive Dashboard'!$C$4="All","<>",'Interactive Dashboard'!$C$4),' Sales analysis'!$F$2:$F$1001,IF('Interactive Dashboard'!$H$4="All","<>",'Interactive Dashboard'!$H$4),' Sales analysis'!$C$2:$C$1001,IF('Interactive Dashboard'!$M$4="All","<>",'Interactive Dashboard'!$M$4)) -> 100500.7 | R9: =IFERROR(INDEX($O$2:$O$10,MATCH(S9,$P$2:$P$10,0)),"") -> Rahul | S9: =IFERROR(LARGE($P$2:$P$10,8),0) -> 3886212
C10: Unknown | E10: Sep | F10: =SUMIFS(' Sales analysis'!$H$2:$H$1001,' Sales analysis'!$E$2:$E$1001,IF('Interactive Dashboard'!$C$4="All","<>",'Interactive Dashboard'!$C$4),' Sales analysis'!$F$2:$F$1001,IF('Interactive Dashboard'!$H$4="All","<>",'Interactive Dashboard'!$H$4),' Sales analysis'!$C$2:$C$1001,IF('Interactive Dashboard'!$M$4="All","<>",'Interactive Dashboard'!$M$4),' Sales analysis'!$B$2:$B$1001,">="&DATE(2025,9,1),' Sales analysis'!$B$2:$B$1001,"<"&EDATE(DATE(2025,9,1),1)) -> 2742406 | O10: Aarav | P10: =SUMIFS(' Sales analysis'!$H$2:$H$1001,' Sales analysis'!$C$2:$C$1001,O10,' Sales analysis'!$E$2:$E$1001,IF('Interactive Dashboard'!$C$4="All","<>",'Interactive Dashboard'!$C$4),' Sales analysis'!$F$2:$F$1001,IF('Interactive Dashboard'!$H$4="All","<>",'Interactive Dashboard'!$H$4),' Sales analysis'!$C$2:$C$1001,IF('Interactive Dashboard'!$M$4="All","<>",'Interactive Dashboard'!$M$4)) -> 4288975.7 | R10: =IFERROR(INDEX($O$2:$O$10,MATCH(S10,$P$2:$P$10,0)),"") -> Unknown | S10: =IFERROR(LARGE($P$2:$P$10,9),0) -> 100500.7
C11: Aarav | E11: Oct | F11: =SUMIFS(' Sales analysis'!$H$2:$H$1001,' Sales analysis'!$E$2:$E$1001,IF('Interactive Dashboard'!$C$4="All","<>",'Interactive Dashboard'!$C$4),' Sales analysis'!$F$2:$F$1001,IF('Interactive Dashboard'!$H$4="All","<>",'Interactive Dashboard'!$H$4),' Sales analysis'!$C$2:$C$1001,IF('Interactive Dashboard'!$M$4="All","<>",'Interactive Dashboard'!$M$4),' Sales analysis'!$B$2:$B$1001,">="&DATE(2025,10,1),' Sales analysis'!$B$2:$B$1001,"<"&EDATE(DATE(2025,10,1),1)) -> 3161107.8 | R11: =IFERROR(INDEX($O$2:$O$10,MATCH(S11,$P$2:$P$10,0)),"") | S11: =IFERROR(LARGE($P$2:$P$10,10),0) -> 0
E12: Nov | F12: =SUMIFS(' Sales analysis'!$H$2:$H$1001,' Sales analysis'!$E$2:$E$1001,IF('Interactive Dashboard'!$C$4="All","<>",'Interactive Dashboard'!$C$4),' Sales analysis'!$F$2:$F$1001,IF('Interactive Dashboard'!$H$4="All","<>",'Interactive Dashboard'!$H$4),' Sales analysis'!$C$2:$C$1001,IF('Interactive Dashboard'!$M$4="All","<>",'Interactive Dashboard'!$M$4),' Sales analysis'!$B$2:$B$1001,">="&DATE(2025,11,1),' Sales analysis'!$B$2:$B$1001,"<"&EDATE(DATE(2025,11,1),1)) -> 3077908.8
E13: Dec | F13: =SUMIFS(' Sales analysis'!$H$2:$H$1001,' Sales analysis'!$E$2:$E$1001,IF('Interactive Dashboard'!$C$4="All","<>",'Interactive Dashboard'!$C$4),' Sales analysis'!$F$2:$F$1001,IF('Interactive Dashboard'!$H$4="All","<>",'Interactive Dashboard'!$H$4),' Sales analysis'!$C$2:$C$1001,IF('Interactive Dashboard'!$M$4="All","<>",'Interactive Dashboard'!$M$4),' Sales analysis'!$B$2:$B$1001,">="&DATE(2025,12,1),' Sales analysis'!$B$2:$B$1001,"<"&EDATE(DATE(2025,12,1),1)) -> 3166955.6
